Workbook

Sheet Read me
A1: ZCR 5 — Detailed cyber security risk assessment
A2: Kanangra Creek Hydro Station · IEC 62443-3-2 · Document 05 of 12 · DRAFT · 14 Sept 2026
A5: PURPOSE
B6: ZCR 5 assesses each zone and conduit in detail: threat, vulnerability, consequence, likelihood, unmitigated risk, existing countermeasures and residual risk. It is the step that turns the consequence-driven partition of ZCR 3 into a prioritised remediation backlog.
A8: PREREQUISITE
B9: ZCR 4 (tolerable risk criteria) must be APPROVED before this sheet is populated. Criteria agreed after the assessment drift toward wherever the findings landed, which makes the assessment unfalsifiable. If document 04 is unsigned, stop here.
A11: HOW TO USE
B12: 1. 'Risk register' is the working sheet. Yellow cells are inputs; everything else is calculated.
B13: 2. Consequence ratings are inherited from ZCR 2 scenarios S-01..S-10 — do not re-derive them here.
B14: 3. Likelihood is assessed twice: unmitigated (no countermeasures) and residual (with existing controls).
B15: 4. Risk bands are looked up from the ZCR 4 matrix on the 'Scales' sheet. Do not type a band by hand.
B16: 5. 'SL gap' tracks SL-T against SL-A. The delta is the remediation backlog — that is the operating loop.
B17: 6. 'Treatment plan' filters everything not tolerable under the ZCR 4 acceptance criteria.
A19: TWO RULES CARRIED FROM ZCR 4
B20: • Safety consequence 5 is NEVER accepted on likelihood grounds alone. A low-likelihood fatality is still a fatality, and 'unlikely' is not a control.
B21: • No treatment may be applied inside a protective function. A control that can fail closed on a protection or safety function has made the plant less safe, not more.
A23: THREAT SOURCE
B24: MITRE ATT&CK for ICS, content version v19.2 (verified 14 Sept 2026 against attack.mitre.org). Technique IDs are version-sensitive: T0855, T0856, T0803, T0804, T0857, T0839 and T0891 appear in older material and have been superseded by T1691-T1695. The 'ATT&CK mapping' sheet records the version so a future reader knows which release the mapping was built against.
A26: STATUS OF THIS WORKBOOK
B27: DRAFT. Likelihood values are the assessor's judgement and are the single most contestable content here. They are threat-informed, not actuarial — there is no dataset of hydro station compromises from which to derive frequencies, and pretending otherwise produces false precision.
A29: FICTIONAL FACILITY
B30: Kanangra Creek is a worked example modelled on a real small run-of-river architecture. It describes no actual asset. Every operating assumption is declared as an assumption in document 01 §6.

Sheet Summary
A1: Assessment summary
A2: All figures are live-linked to the risk register. Nothing on this sheet is typed.
A4: RESIDUAL RISK PROFILE
A5: Band | B5: Count | C5: Share | D5: Acceptance authority
A6: E — Extreme | B6: =COUNTIF('Risk register'!$O$5:$O$44,"E") | C6: =B6/$B$10 | D6: Board or equivalent governing body
A7: H — High | B7: =COUNTIF('Risk register'!$O$5:$O$44,"H") | C7: =B7/$B$10 | D7: Asset owner executive
A8: M — Medium | B8: =COUNTIF('Risk register'!$O$5:$O$44,"M") | C8: =B8/$B$10 | D8: Asset manager
A9: L — Low | B9: =COUNTIF('Risk register'!$O$5:$O$44,"L") | C9: =B9/$B$10 | D9: Site
A10: Total | B10: =SUM(B6:B9) | C10: =SUM(C6:C9)
A12: RISK REDUCTION DELIVERED BY EXISTING CONTROLS
A13: Band | B13: Unmitigated | C13: Residual | D13: Change
A14: E — Extreme | B14: =COUNTIF('Risk register'!$L$5:$L$44,"E") | C14: =COUNTIF('Risk register'!$O$5:$O$44,"E") | D14: =C14-B14
A15: H — High | B15: =COUNTIF('Risk register'!$L$5:$L$44,"H") | C15: =COUNTIF('Risk register'!$O$5:$O$44,"H") | D15: =C15-B15
A16: M — Medium | B16: =COUNTIF('Risk register'!$L$5:$L$44,"M") | C16: =COUNTIF('Risk register'!$O$5:$O$44,"M") | D16: =C16-B16
A17: L — Low | B17: =COUNTIF('Risk register'!$L$5:$L$44,"L") | C17: =COUNTIF('Risk register'!$O$5:$O$44,"L") | D17: =C17-B17
A19: LIFE-SAFETY OVERRIDE (ZCR 4 s5, as corrected 14 Sept 2026)
A20: Risks with a credible path to fatality — safety 5, or environment 5 by uncontrolled water release (treated regardless of band) | B20: =COUNTIFS('Risk register'!$I$5:$I$44,"Safety",'Risk register'!$J$5:$J$44,5)+COUNTIFS('Risk register'!$I$5:$I$44,"Environment",'Risk register'!$J$5:$J$44,5)
A22: TREATMENT LOAD
A23: Risks flagged as requiring treatment | B23: =COUNTIF('Risk register'!$P$5:$P$44,"YES")+COUNTIF('Risk register'!$P$5:$P$44,"YES - life-safety override")
A24: Risks tolerable with justification and monitoring | B24: =COUNTIF('Risk register'!$P$5:$P$44,"Justify & monitor")
A26: WHAT THE NUMBERS SAY
A27: • The residual Extremes cluster in three places, and none of them is the turbine. They are the intake (uncontrolled physical access to a gate controller), the vendor remote access path (shared credentials, no session recording), and recovery (backups on the same domain as the host that would be encrypted).
A28: • Existing controls move very little. The unmitigated and residual profiles are close because most countermeasures in place are detective and periodic — annual protection testing, monthly inspection, an annual firewall review — against threats that act in minutes. That is the finding, not the arithmetic.
A29: • The single highest residual risk, R-22, has no network treatment at all. An adversary standing at the intake RTU is not mitigated by anything in the network design, which is why the treatment is detection and command validation rather than access control.
A30: • Two of the top three findings are contractual rather than technical: 62443-2-4 obligations on the vendor and a restore-tested off-site backup. That is normal, and it is why the CRS matters more than the firewall.
A32: ✔ CALIBRATION — RESOLVED BY ROUTE 2, APPROVED 14 SEPT 2026
A33: The register originally flagged 39 of 40 risks for treatment, with 17 risks carrying safety consequence 5. Most of those 5s were INHERITED from what a risk enabled rather than what it directly achieved. Route 2 has been applied: each risk is now rated at the consequence it achieves at the point it reaches, without traversing a further zone boundary or defeating a further control. The escalation chains are carried on the 'Attack path' sheet.
A34: Renoted: R-12, R-17, R-26, R-35, R-38, R-39 — from safety 5 to availability 4. R-20 was already rated directly and is unchanged. Effect: the Extreme band falls from 17 to 11, and the SAFETY-5 population falls from 17 to 11. Route 2 also exposed a drafting gap in ZCR 4 s5: the override named only the Safety category, while ZCR 4's own environment-5 band describes uncontrolled water release affecting third parties, which is a fatality mechanism. Document 04 has been corrected and the override now reads LIFE-SAFETY, covering 16 risks.
A35: WHAT ROUTE 2 DID NOT FIX, STATED PLAINLY. The treatment load is still 39 of 40, because the ZCR 4 criteria require treatment at High as well as Extreme, and a plant with periodic detective controls against threats that act in minutes genuinely sits there before treatment. Route 2 was never going to change that number and it has not. What it changed is the ranking underneath it.
A36: That ranking is now explicit. Column U of the register carries a priority score: consequence x residual likelihood, with safety-5 lifted above everything else because ZCR 4 makes it non-negotiable. The treatment plan is ordered on that score. 'What do I fund first' has an answer that does not depend on the reader's patience.
A37: ROUTES NOT TAKEN. Route 1 (accept the 97% and defend the treatment ordering instead) is defensible but does the same work with less transparency. Route 3 (re-examine residual likelihood) asks a question that can only be answered by testing controls that do not exist on a fictional facility — it is an engineering answer to a rating question.
A38: THE CONDITION ON ALL OF THIS. All six renotings hold ONLY because the hardwired overspeed trip is independent of every programmable device (assumption A-01, contracted as GC-2) and the gate closure-rate limit sits outside programmable logic (CRS-009). If A-01 is false, all six return to consequence 5, the Extreme band returns to 17, and Z-02 rises to SL-T 4. A-01 is the first thing to verify on site.
A39: Recorded here and in the ZCR 7 approval record, as required. An unexplained 97% treatment rate reads as an assessor who did not calibrate; an explained one reads as an assessor who did.

Sheet Risk register
A1: ZCR 5 — Detailed risk register
A2: Kanangra Creek Hydro Station · 40 risks across 8 zones and 12 conduits · Threat source: MITRE ATT&CK for ICS v19.2 · Yellow cells are inputs; risk bands are calculated from the ZCR 4 matrix on 'Scales'.
A4: Risk ID | B4: Zone / Conduit | C4: Element | D4: SL-T | E4: Threat scenario | F4: ATT&CK for ICS technique(s) | G4: Vulnerability / weakness | H4: Cons. ref | I4: Primary category | J4: Cons. (1-5) | K4: Likelihood unmitigated | L4: Unmitigated risk | M4: Existing countermeasures | N4: Likelihood residual | O4: Residual risk | P4: Treatment required? | Q4: Owner | R4: Target date | S4: Assessor note | T4: Escalates to (Route 2) | U4: Priority score (C x Lres)
A5: R-01 | B5: Z-01 | C5: Generator protection relay | D5: 3 | E5: Adversary with engineering workstation access alters the active protection setting group so that differential and overspeed elements no longer operate at the intended thresholds. | F5: T0836 Modify Parameter; T0837 Loss of Protection | G5: Relay setting software is installed on the shared engineering workstation. Setting changes are not independently verified against an approved settings schedule. | H5: S-04 | I5: Safety | J5: 5 | K5: 3 | L5: =INDEX(Scales!$B$24:$F$28,6-K5,J5) | M5: Powerhouse physical access control. Relay local passwords. Annual protection testing. | N5: 2 | O5: =INDEX(Scales!$B$24:$F$28,6-N5,J5) | P5: =IF(AND(J5=5,OR(I5="Safety",I5="Environment")),"YES - life-safety override",IF(OR(O5="E",O5="H"),"YES",IF(O5="M","Justify & monitor","No"))) | S5: Annual testing detects a changed setting up to 12 months late. That interval IS the exposure. | U5: =J5*N5
A6: R-02 | B6: Z-01 | C6: Protection trip outputs | D6: 3 | E6: Trip outputs are blocked or the relay is placed out of service, leaving equipment running unprotected until a fault occurs. | F6: T0837 Loss of Protection; T1691 Block Operational Technology Message | G6: Out-of-service state is indicated locally but is not alarmed to the control centre. | H6: S-04 | I6: Safety | J6: 5 | K6: 3 | L6: =INDEX(Scales!$B$24:$F$28,6-K6,J6) | M6: Local indication. Operator rounds twice weekly. | N6: 2 | O6: =INDEX(Scales!$B$24:$F$28,6-N6,J6) | P6: =IF(AND(J6=5,OR(I6="Safety",I6="Environment")),"YES - life-safety override",IF(OR(O6="E",O6="H"),"YES",IF(O6="M","Justify & monitor","No"))) | S6: The TRITON pattern: the target is the system that protects the process, not the process. | U6: =J6*N6
A7: R-03 | B7: Z-01 | C7: IEC 61850 process bus | D7: 3 | E7: GOOSE messages are injected or replayed on the process bus to force or inhibit a trip. | F7: T1692 Unauthorized Message; T0830 Adversary-in-the-Middle | G7: GOOSE has no authentication in the baseline configuration. Process bus shares physical infrastructure with the station bus. | H7: S-04 | I7: Safety | J7: 5 | K7: 2 | L7: =INDEX(Scales!$B$24:$F$28,6-K7,J7) | M7: Process bus is physically within the relay room. VLAN separation from station bus. | N7: 2 | O7: =INDEX(Scales!$B$24:$F$28,6-N7,J7) | P7: =IF(AND(J7=5,OR(I7="Safety",I7="Environment")),"YES - life-safety override",IF(OR(O7="E",O7="H"),"YES",IF(O7="M","Justify & monitor","No"))) | S7: Requires physical presence plus IACS-specific knowledge. VLAN separation is not authentication. | U7: =J7*N7
A8: R-04 | B8: Z-01 | C8: Relay firmware | D8: 3 | E8: Relay firmware is replaced with a modified image that behaves correctly under test and incorrectly under fault. | F8: T1693 Modify Firmware | G8: Firmware authenticity is not verified at install. Firmware is obtained from vendor portals over the vendor remote access path. | H8: S-04 | I8: Safety | J8: 5 | K8: 2 | L8: =INDEX(Scales!$B$24:$F$28,6-K8,J8) | M8: Vendor-supplied firmware only. Change management approval. | N8: 2 | O8: =INDEX(Scales!$B$24:$F$28,6-N8,J8) | P8: =IF(AND(J8=5,OR(I8="Safety",I8="Environment")),"YES - life-safety override",IF(OR(O8="E",O8="H"),"YES",IF(O8="M","Justify & monitor","No"))) | S8: Low likelihood, maximum consequence, and effectively undetectable by operational testing. | U8: =J8*N8
A9: R-05 | B9: Z-02 | C9: Digital governor | D9: 3 | E9: Governor control logic is downloaded with modified gate sequencing, producing overspeed on load rejection or on an out-of-sync start. | F9: T0843 Program Download; T0889 Modify Program; T0879 Damage to Property | G9: Governor programming interface has no per-user authentication. Logic is not integrity-checked after download. | H9: S-01 | I9: Safety | J9: 5 | K9: 3 | L9: =INDEX(Scales!$B$24:$F$28,6-K9,J9) | M9: Hardwired overspeed trip (ASSUMPTION A-01). Physical access control. | N9: 2 | O9: =INDEX(Scales!$B$24:$F$28,6-N9,J9) | P9: =IF(AND(J9=5,OR(I9="Safety",I9="Environment")),"YES - life-safety override",IF(OR(O9="E",O9="H"),"YES",IF(O9="M","Justify & monitor","No"))) | S9: SL-T 3 depends entirely on A-01 holding. If the overspeed trip is programmable, this becomes the dominant risk and SL-T rises to 4. | U9: =J9*N9
A10: R-06 | B10: Z-02 | C10: Wicket gate / inlet valve closure rate | D10: 3 | E10: Closure-rate limit is altered so that a commanded closure generates a pressure transient beyond penstock design. | F10: T0836 Modify Parameter; T0831 Manipulation of Control | G10: The closure-rate limit is enforced in governor software, i.e. inside the zone an adversary would already control. | H10: S-02 | I10: Safety | J10: 5 | K10: 3 | L10: =INDEX(Scales!$B$24:$F$28,6-K10,J10) | M10: Mechanical relief valve (to be confirmed). Change management. | N10: 2 | O10: =INDEX(Scales!$B$24:$F$28,6-N10,J10) | P10: =IF(AND(J10=5,OR(I10="Safety",I10="Environment")),"YES - life-safety override",IF(OR(O10="E",O10="H"),"YES",IF(O10="M","Justify & monitor","No"))) | S10: OPEN QUESTION for the asset owner: where is the closure-rate limit actually enforced? If software-only, no compensating control exists. | U10: =J10*N10
A11: R-07 | B11: Z-02 | C11: Unit control PLC | D11: 3 | E11: PLC is placed in PROGRAM or STOP mode, halting the unit or suspending interlock execution. | F11: T0858 Change Operating Mode; T0816 Device Restart/Shutdown | G11: Keyswitch is left in REMOTE. Mode change is not alarmed. | H11: S-05 | I11: Availability | J11: 4 | K11: 4 | L11: =INDEX(Scales!$B$24:$F$28,6-K11,J11) | M11: Mode state is visible on the HMI if an operator is watching. | N11: 3 | O11: =INDEX(Scales!$B$24:$F$28,6-N11,J11) | P11: =IF(AND(J11=5,OR(I11="Safety",I11="Environment")),"YES - life-safety override",IF(OR(O11="E",O11="H"),"YES",IF(O11="M","Justify & monitor","No"))) | S11: Station is normally unattended. 'Visible on the HMI' is a weak control in an unattended plant. | U11: =J11*N11
A12: R-08 | B12: Z-02 | C12: Unit start/stop | D12: 3 | E12: Unauthorised start or stop commands are issued directly to the unit control PLC. | F12: T1692 Unauthorized Message; T0813 Denial of Control | G12: Command source is not authenticated at the PLC; any host on the supervisory VLAN can write. | H12: S-05 | I12: Availability | J12: 4 | K12: 4 | L12: =INDEX(Scales!$B$24:$F$28,6-K12,J12) | M12: Control centre logs dispatch actions. Unit protection prevents out-of-sync closure. | N12: 3 | O12: =INDEX(Scales!$B$24:$F$28,6-N12,J12) | P12: =IF(AND(J12=5,OR(I12="Safety",I12="Environment")),"YES - life-safety override",IF(OR(O12="E",O12="H"),"YES",IF(O12="M","Justify & monitor","No"))) | S12: SOCI: OT offline is a significant impact on availability, triggering the 12-hour report, not 72. | U12: =J12*N12
A13: R-09 | B13: Z-02 | C13: Automatic voltage regulator | D13: 3 | E13: Excitation setpoints are manipulated, driving the generator toward loss of field or over-excitation. | F13: T0836 Modify Parameter; T0831 Manipulation of Control | G13: AVR is on a proprietary serial link with no authentication; reachable from the unit control cabinet. | H13: S-01 | I13: Financial | J13: 4 | K13: 2 | L13: =INDEX(Scales!$B$24:$F$28,6-K13,J13) | M13: Generator protection (loss of field, over-excitation elements). | N13: 2 | O13: =INDEX(Scales!$B$24:$F$28,6-N13,J13) | P13: =IF(AND(J13=5,OR(I13="Safety",I13="Environment")),"YES - life-safety override",IF(OR(O13="E",O13="H"),"YES",IF(O13="M","Justify & monitor","No"))) | S13: Protection is the compensating control — which is why R-01 and R-02 matter more than they look. | U13: =J13*N13
A14: R-10 | B14: Z-03 | C14: Cooling water / lube oil control | D14: 2 | E14: Setpoints are drifted slowly so that bearing and winding temperatures rise toward but not through alarm thresholds. | F14: T0836 Modify Parameter; T0831 Manipulation of Control | G14: Auxiliary setpoints are not baselined; no alerting on setpoint change, only on process value. | H14: S-08 | I14: Availability | J14: 4 | K14: 3 | L14: =INDEX(Scales!$B$24:$F$28,6-K14,J14) | M14: High-temperature trips via protection. Monthly maintenance inspection. | N14: 2 | O14: =INDEX(Scales!$B$24:$F$28,6-N14,J14) | P14: =IF(AND(J14=5,OR(I14="Safety",I14="Environment")),"YES - life-safety override",IF(OR(O14="E",O14="H"),"YES",IF(O14="M","Justify & monitor","No"))) | S14: The slow variant is the dangerous one: it stays inside alarm tolerance and is invisible to threshold alarming. | U14: =J14*N14
A15: R-11 | B15: Z-03 | C15: Drainage and dewatering | D15: 2 | E15: Drainage pumps are stopped or inhibited, allowing water ingress to reach electrical equipment in the powerhouse. | F15: T0881 Service Stop; T0813 Denial of Control | G15: Pump run status is monitored; pump inhibit state is not. | H15: S-08 | I15: Availability | J15: 4 | K15: 3 | L15: =INDEX(Scales!$B$24:$F$28,6-K15,J15) | M15: Sump high-level alarm to control centre. | N15: 2 | O15: =INDEX(Scales!$B$24:$F$28,6-N15,J15) | P15: =IF(AND(J15=5,OR(I15="Safety",I15="Environment")),"YES - life-safety override",IF(OR(O15="E",O15="H"),"YES",IF(O15="M","Justify & monitor","No"))) | S15: High-level alarm is the last line, not the first. It fires when the problem is already physical. | U15: =J15*N15
A16: R-12 | B16: Z-03 | C16: Auxiliaries PLC as pivot | D16: 2 | E16: The auxiliaries PLC, being lower-assurance, is used as a staging point to reach the unit control zone. | F16: T0867 Lateral Tool Transfer; T0846 Remote System Discovery | G16: Conduit C-03 permits broader traffic than the permissive exchange requires. | H16: S-08 | I16: Availability | J16: 4 | K16: 3 | L16: =INDEX(Scales!$B$24:$F$28,6-K16,J16) | M16: VLAN separation between Z-03 and Z-02. | N16: 3 | O16: =INDEX(Scales!$B$24:$F$28,6-N16,J16) | P16: =IF(AND(J16=5,OR(I16="Safety",I16="Environment")),"YES - life-safety override",IF(OR(O16="E",O16="H"),"YES",IF(O16="M","Justify & monitor","No"))) | S16: ROUTE 2 — rated at direct consequence. An adversary on the auxiliaries PLC can stop cooling, lube oil and drainage; the machine trips and may need bearing inspection. It does not reach the turbine unless it also crosses into Z-02. The cascade is carried on 'Attack path', not in this cell. | T16: S-01 via C-03 into Z-02 (lateral movement from a lower-assurance zone) | U16: =J16*N16
A17: R-13 | B17: Z-04 | C17: Control room HMI | D17: 2 | E17: Displayed process values are manipulated so that operators and the control centre act on a false picture. | F17: T0832 Manipulation of View; T0829 Loss of View | G17: HMI tag values are trusted without cross-check against an independent source. | H17: S-07 | I17: Availability | J17: 3 | K17: 3 | L17: =INDEX(Scales!$B$24:$F$28,6-K17,J17) | M17: Historian provides an independent record if compared. | N17: 3 | O17: =INDEX(Scales!$B$24:$F$28,6-N17,J17) | P17: =IF(AND(J17=5,OR(I17="Safety",I17="Environment")),"YES - life-safety override",IF(OR(O17="E",O17="H"),"YES",IF(O17="M","Justify & monitor","No"))) | S17: Derivative consequence: its true rating is the rating of whatever it conceals. | U17: =J17*N17
A18: R-14 | B18: Z-04 | C18: Alarm system | D18: 2 | E18: Alarms are suppressed or thresholds widened so that a developing condition is not annunciated. | F18: T0878 Alarm Suppression; T0838 Modify Alarm Settings | G18: Alarm configuration changes are not logged to an independent store. | H18: S-07 | I18: Safety | J18: 4 | K18: 3 | L18: =INDEX(Scales!$B$24:$F$28,6-K18,J18) | M18: Alarm history retained in the historian. | N18: 3 | O18: =INDEX(Scales!$B$24:$F$28,6-N18,J18) | P18: =IF(AND(J18=5,OR(I18="Safety",I18="Environment")),"YES - life-safety override",IF(OR(O18="E",O18="H"),"YES",IF(O18="M","Justify & monitor","No"))) | S18: Alarm suppression is rarely the objective. It is what makes the objective survivable for the attacker. | U18: =J18*N18
A19: R-15 | B19: Z-04 | C19: SCADA servers | D19: 2 | E19: SCADA is denied, removing remote supervision and control of an unattended station. | F19: T0814 Denial of Service; T0815 Denial of View | G19: Redundant pair shares a single switch stack and a single power supply path. | H19: S-05 | I19: Availability | J19: 3 | K19: 3 | L19: =INDEX(Scales!$B$24:$F$28,6-K19,J19) | M19: Redundant server pair. Local manual control available. | N19: 2 | O19: =INDEX(Scales!$B$24:$F$28,6-N19,J19) | P19: =IF(AND(J19=5,OR(I19="Safety",I19="Environment")),"YES - life-safety override",IF(OR(O19="E",O19="H"),"YES",IF(O19="M","Justify & monitor","No"))) | S19: Local manual control is the real mitigation, and it depends on assumption A-10. | U19: =J19*N19
A20: R-16 | B20: Z-04 | C20: GPS / NTP time source | D20: 2 | E20: GPS signal is spoofed, corrupting protection timestamps and sequence-of-event records. | F20: T0830 Adversary-in-the-Middle | G20: GPS is unauthenticated by nature. No holdover monitoring or sanity check against a second source. | H20: S-07 | I20: Regulatory | J20: 3 | K20: 3 | L20: =INDEX(Scales!$B$24:$F$28,6-K20,J20) | M20: None specific. | N20: 3 | O20: =INDEX(Scales!$B$24:$F$28,6-N20,J20) | P20: =IF(AND(J20=5,OR(I20="Safety",I20="Environment")),"YES - life-safety override",IF(OR(O20="E",O20="H"),"YES",IF(O20="M","Justify & monitor","No"))) | S20: A small asset with consequence disproportionate to its cost. Post-event forensics become untrustworthy. | U20: =J20*N20
A21: R-17 | B21: Z-04 | C21: Operator credentials | D21: 2 | E21: Credentials are harvested from an HMI session and reused to reach the unit control zone. | F21: T0859 Valid Accounts; T1694 Insecure Credentials | G21: Shared operator account in use. No MFA on the supervisory zone. | H21: S-05 | I21: Availability | J21: 4 | K21: 3 | L21: =INDEX(Scales!$B$24:$F$28,6-K21,J21) | M21: Physical access control to the control room. | N21: 3 | O21: =INDEX(Scales!$B$24:$F$28,6-N21,J21) | P21: =IF(AND(J21=5,OR(I21="Safety",I21="Environment")),"YES - life-safety override",IF(OR(O21="E",O21="H"),"YES",IF(O21="M","Justify & monitor","No"))) | S21: ROUTE 2 — rated at direct consequence. Harvested operator credentials give operator-level authority: dispatch, setpoint and alarm actions the HMI is entitled to make. Reaching the governor programming interface is a further step with a further control in the way. | T21: S-01 via C-02 (operator credential reused against the governor programming interface) | U21: =J21*N21
A22: R-18 | B22: Z-05a | C22: Engineering workstation + backup store | D22: 3 | E22: Ransomware or wiper encrypts controller logic, relay settings, SCADA configuration AND the backups, which are on the same site and reachable from the same host. | F22: T0809 Data Destruction; T0826 Loss of Availability | G22: Backups are on-site, on the same domain, reachable from the workstation that would be compromised. Restore has not been tested. | H22: S-09 | I22: Availability | J22: 5 | K22: 4 | L22: =INDEX(Scales!$B$24:$F$28,6-K22,J22) | M22: Daily backup job. Antivirus. | N22: 3 | O22: =INDEX(Scales!$B$24:$F$28,6-N22,J22) | P22: =IF(AND(J22=5,OR(I22="Safety",I22="Environment")),"YES - life-safety override",IF(OR(O22="E",O22="H"),"YES",IF(O22="M","Justify & monitor","No"))) | S22: THE scenario that turns a recoverable incident into an unrecoverable one. Directly engages CIRMP s8C: recover and restore critical systems, maintain availability during restoration. | U22: =J22*N22
A23: R-19 | B23: Z-05a | C23: Controller project files | D23: 3 | E23: A project file is infected so that the next legitimate download carries modified logic into Z-01 or Z-02. | F23: T0873 Project File Infection; T0889 Modify Program | G23: Project files are not integrity-checked or signed. No golden-copy comparison before download. | H23: S-01 | I23: Safety | J23: 5 | K23: 3 | L23: =INDEX(Scales!$B$24:$F$28,6-K23,J23) | M23: Change management approval for downloads. | N23: 2 | O23: =INDEX(Scales!$B$24:$F$28,6-N23,J23) | P23: =IF(AND(J23=5,OR(I23="Safety",I23="Environment")),"YES - life-safety override",IF(OR(O23="E",O23="H"),"YES",IF(O23="M","Justify & monitor","No"))) | S23: Approval governs the intent to download, not the content of what is downloaded. | U23: =J23*N23
A24: R-20 | B24: Z-05b | C24: Historian and documentation | D24: 2 | E24: Relay settings, network diagrams and process data are exfiltrated to support a later, targeted operation. | F24: T0882 Theft of Operational Information; T0811 Data from Information Repositories | G24: Engineering documentation is stored unencrypted on the local file share. | H24: S-09 | I24: Regulatory | J24: 3 | K24: 4 | L24: =INDEX(Scales!$B$24:$F$28,6-K24,J24) | M24: Domain authentication. | N24: 3 | O24: =INDEX(Scales!$B$24:$F$28,6-N24,J24) | P24: =IF(AND(J24=5,OR(I24="Safety",I24="Environment")),"YES - life-safety override",IF(OR(O24="E",O24="H"),"YES",IF(O24="M","Justify & monitor","No"))) | S24: ROUTE 2 — already rated at direct consequence, and left unchanged. Low direct harm, high enabling value: it is the reconnaissance that makes R-05 and R-19 achievable. The enabling value is on 'Attack path'. | T24: R-05, R-19 — reconnaissance product; no direct escalation of its own | U24: =J24*N24
A25: R-21 | B25: Z-05a | C25: Engineering toolchain | D25: 3 | E25: The workstation's legitimate programming capability is used to reprogram protection or unit control directly. | F25: T0843 Program Download; T0821 Modify Controller Tasking | G25: One workstation holds toolchains for governor, PLC and relays with no separation of duty. | H25: S-01 | I25: Safety | J25: 5 | K25: 3 | L25: =INDEX(Scales!$B$24:$F$28,6-K25,J25) | M25: Physical access control. Change management. | N25: 2 | O25: =INDEX(Scales!$B$24:$F$28,6-N25,J25) | P25: =IF(AND(J25=5,OR(I25="Safety",I25="Environment")),"YES - life-safety override",IF(OR(O25="E",O25="H"),"YES",IF(O25="M","Justify & monitor","No"))) | S25: This is the asset that makes Z-05 rate above Z-04. Purdue level is not consequence. | U25: =J25*N25
A26: R-22 | B26: Z-06 | C26: Intake RTU — physical | D26: 3 | E26: An adversary reaches the intake structure on foot and connects directly to the RTU, commanding gates and falsifying level reporting. | F26: T0864 Transient Cyber Asset; T0831 Manipulation of Control | G26: Physical protection is a fence and a padlock, 4.2 km from the powerhouse, with no intrusion detection and no camera. | H26: S-03 | I26: Environment | J26: 5 | K26: 4 | L26: =INDEX(Scales!$B$24:$F$28,6-K26,J26) | M26: None effective. Assumption A-03 states access is uncontrolled. | N26: 4 | O26: =INDEX(Scales!$B$24:$F$28,6-N26,J26) | P26: =IF(AND(J26=5,OR(I26="Safety",I26="Environment")),"YES - life-safety override",IF(OR(O26="E",O26="H"),"YES",IF(O26="M","Justify & monitor","No"))) | S26: THE HIGHEST RESIDUAL RISK IN THIS ASSESSMENT. No network control mitigates an adversary standing at the terminal. | U26: =J26*N26
A27: R-23 | B27: Z-06 | C27: Radio link | D27: 3 | E27: A rogue master injects DNP3 commands over the licensed radio link to move gates. | F27: T0848 Rogue Master; T0860 Wireless Compromise; T1692 Unauthorized Message | G27: DNP3 without Secure Authentication. Link encryption status unconfirmed. | H27: S-03 | I27: Environment | J27: 5 | K27: 3 | L27: =INDEX(Scales!$B$24:$F$28,6-K27,J27) | M27: Licensed narrowband radio, non-standard equipment. | N27: 3 | O27: =INDEX(Scales!$B$24:$F$28,6-N27,J27) | P27: =IF(AND(J27=5,OR(I27="Safety",I27="Environment")),"YES - life-safety override",IF(OR(O27="E",O27="H"),"YES",IF(O27="M","Justify & monitor","No"))) | S27: OPEN: does the RTU support DNP3 Secure Authentication? An SL-C question that decides whether C-06's SL-T 3 is achievable or aspirational. | U27: =J27*N27
A28: R-24 | B28: Z-06 | C28: Level instrumentation | D28: 3 | E28: Headwater and tailwater telemetry is falsified so that every automated and human response is wrong by design. | F28: T0832 Manipulation of View; T1692 Unauthorized Message | G28: No independent second source for level. Automation and operators share one input. | H28: S-03 | I28: Environment | J28: 5 | K28: 3 | L28: =INDEX(Scales!$B$24:$F$28,6-K28,J28) | M28: Operator familiarity with seasonal norms. | N28: 3 | O28: =INDEX(Scales!$B$24:$F$28,6-N28,J28) | P28: =IF(AND(J28=5,OR(I28="Safety",I28="Environment")),"YES - life-safety override",IF(OR(O28="E",O28="H"),"YES",IF(O28="M","Justify & monitor","No"))) | S28: The falsification variant is more dangerous than direct gate command, because it corrupts the response as well as the state. | U28: =J28*N28
A29: R-25 | B29: Z-06 | C29: Cellular backup path | D29: 3 | E29: The standby cellular path is discovered and used as an always-available route into the intake zone. | F29: T0883 Internet Accessible Device; T0822 External Remote Services | G29: APN-based access with no per-device certificate. Path is standby but permanently connected. | H29: S-03 | I29: Environment | J29: 5 | K29: 3 | L29: =INDEX(Scales!$B$24:$F$28,6-K29,J29) | M29: Private APN. | N29: 3 | O29: =INDEX(Scales!$B$24:$F$28,6-N29,J29) | P29: =IF(AND(J29=5,OR(I29="Safety",I29="Environment")),"YES - life-safety override",IF(OR(O29="E",O29="H"),"YES",IF(O29="M","Justify & monitor","No"))) | S29: A standby path that is permanently connected is not a standby path. It is a second front door. | U29: =J29*N29
A30: R-26 | B30: Z-07 | C30: Maintenance laptops | D30: 3 | E30: A contractor laptop that was on an uncontrolled network is connected directly to a control zone. | F30: T0864 Transient Cyber Asset; T0867 Lateral Tool Transfer | G30: No pre-connection scanning, no dedicated site laptops, no port control on control-zone switches. | H30: S-05 | I30: Availability | J30: 4 | K30: 4 | L30: =INDEX(Scales!$B$24:$F$28,6-K30,J30) | M30: Site induction. Verbal policy. | N30: 3 | O30: =INDEX(Scales!$B$24:$F$28,6-N30,J30) | P30: =IF(AND(J30=5,OR(I30="Safety",I30="Environment")),"YES - life-safety override",IF(OR(O30="E",O30="H"),"YES",IF(O30="M","Justify & monitor","No"))) | S30: ROUTE 2 — rated at direct consequence. A contaminated laptop inside a control zone runs code on control hosts: commodity malware, lost view, forced outage. Turning that into machine damage requires deliberate process manipulation, which is the chain on 'Attack path'. | T30: S-01 / S-02 via deliberate process manipulation once resident in Z-02 or Z-03 | U30: =J30*N30
A31: R-27 | B31: Z-07 | C31: Removable media | D31: 3 | E31: Malware is introduced on USB media used to transfer firmware or configuration backups. | F31: T0847 Replication Through Removable Media; T0895 Autorun Image | G31: No media sanitisation station. USB ports unrestricted on the engineering workstation. | H31: S-09 | I31: Availability | J31: 5 | K31: 3 | L31: =INDEX(Scales!$B$24:$F$28,6-K31,J31) | M31: Antivirus on the workstation. | N31: 3 | O31: =INDEX(Scales!$B$24:$F$28,6-N31,J31) | P31: =IF(AND(J31=5,OR(I31="Safety",I31="Environment")),"YES - life-safety override",IF(OR(O31="E",O31="H"),"YES",IF(O31="M","Justify & monitor","No"))) | S31: The access point with no network control at all. It is how Stuxnet crossed an air gap. | U31: =J31*N31
A32: R-28 | B32: Z-08 | C32: Remote access jump host | D32: 3 | E32: The jump host is compromised and used as the staging point for access to every zone it can reach. | F32: T0822 External Remote Services; T0866 Exploitation of Remote Services | G32: Jump host is internet-reachable by design. Session recording not enabled. | H32: S-10 | I32: Safety | J32: 5 | K32: 3 | L32: =INDEX(Scales!$B$24:$F$28,6-K32,J32) | M32: DMZ firewall. MFA on the jump host. | N32: 2 | O32: =INDEX(Scales!$B$24:$F$28,6-N32,J32) | P32: =IF(AND(J32=5,OR(I32="Safety",I32="Environment")),"YES - life-safety override",IF(OR(O32="E",O32="H"),"YES",IF(O32="M","Justify & monitor","No"))) | S32: The most valuable asset in the SUC to an external adversary, because it is the one designed to be reachable. | U32: =J32*N32
A33: R-29 | B33: Z-08 | C33: DMZ services | D33: 3 | E33: An unpatched internet-facing DMZ service is exploited to obtain a foothold. | F33: T0819 Exploit Public-Facing Application; T0883 Internet Accessible Device | G33: Patch cadence on DMZ hosts is quarterly, aligned to plant outage rather than to threat. | H33: S-10 | I33: Availability | J33: 5 | K33: 3 | L33: =INDEX(Scales!$B$24:$F$28,6-K33,J33) | M33: DMZ firewall. Quarterly patching. | N33: 3 | O33: =INDEX(Scales!$B$24:$F$28,6-N33,J33) | P33: =IF(AND(J33=5,OR(I33="Safety",I33="Environment")),"YES - life-safety override",IF(OR(O33="E",O33="H"),"YES",IF(O33="M","Justify & monitor","No"))) | S33: Patch cadence tied to outage windows is normal in OT and is exactly why compensating controls carry the load. | U33: =J33*N33
A34: R-30 | B34: Z-08 | C34: Firewall rule set | D34: 3 | E34: Rule drift over time opens a path that the as-designed architecture does not contain. | F34: T0846 Remote System Discovery; T0867 Lateral Tool Transfer | G34: No automated comparison of implemented flows against the conduit register. | H34: S-10 | I34: Availability | J34: 5 | K34: 4 | L34: =INDEX(Scales!$B$24:$F$28,6-K34,J34) | M34: Annual firewall review. | N34: 3 | O34: =INDEX(Scales!$B$24:$F$28,6-N34,J34) | P34: =IF(AND(J34=5,OR(I34="Safety",I34="Environment")),"YES - life-safety override",IF(OR(O34="E",O34="H"),"YES",IF(O34="M","Justify & monitor","No"))) | S34: An annual review against a document nobody updated is not a control. This is what an automated conduit-drift check exists to catch. | U34: =J34*N34
A35: R-31 | B35: C-09 | C35: Vendor remote access — supply chain | D35: 3 | E35: An OEM's own environment is compromised and the trusted inbound path is used to reach the plant. The access is legitimate, credentialed, and looks exactly like maintenance. | F35: T0862 Supply Chain Compromise; T0822 External Remote Services | G35: Vendor security posture is not assessed. No 62443-2-4 obligations in the service contract. | H35: S-10 | I35: Safety | J35: 5 | K35: 3 | L35: =INDEX(Scales!$B$24:$F$28,6-K35,J35) | M35: Access on request only. DMZ termination. | N35: 3 | O35: =INDEX(Scales!$B$24:$F$28,6-N35,J35) | P35: =IF(AND(J35=5,OR(I35="Safety",I35="Environment")),"YES - life-safety override",IF(OR(O35="E",O35="H"),"YES",IF(O35="M","Justify & monitor","No"))) | S35: The hardest scenario in this register to detect, because it is indistinguishable from authorised work. Drives the 62443-2-4 requirements in the CRS. | U35: =J35*N35
A36: R-32 | B36: C-09 | C36: Vendor remote access — credentials | D36: 3 | E36: A shared vendor account is reused or leaked and the path is entered without the vendor's knowledge. | F36: T1694 Insecure Credentials; T0859 Valid Accounts | G36: Shared per-vendor accounts rather than per-individual. No just-in-time approval. No session recording. | H36: S-10 | I36: Safety | J36: 5 | K36: 4 | L36: =INDEX(Scales!$B$24:$F$28,6-K36,J36) | M36: Firewall rule permits the vendor source range only. | N36: 3 | O36: =INDEX(Scales!$B$24:$F$28,6-N36,J36) | P36: =IF(AND(J36=5,OR(I36="Safety",I36="Environment")),"YES - life-safety override",IF(OR(O36="E",O36="H"),"YES",IF(O36="M","Justify & monitor","No"))) | S36: Oldsmar was not sophisticated: shared credentials and an operator who happened to be watching the screen. The failure was architectural, not technical. CIRMP s8B now requires phishing-resistant MFA here. | U36: =J36*N36
A37: R-33 | B37: C-06 | C37: Intake conduit | D37: 3 | E37: The conduit itself is the attack surface: unauthenticated DNP3 over a radio link whose far end is physically accessible. | F37: T1692 Unauthorized Message; T0848 Rogue Master | G37: No cryptographic authentication on the link. Commands are trusted on receipt rather than validated against independently sensed conditions. | H37: S-03 | I37: Environment | J37: 5 | K37: 3 | L37: =INDEX(Scales!$B$24:$F$28,6-K37,J37) | M37: Licensed spectrum. Physical remoteness (not a control). | N37: 3 | O37: =INDEX(Scales!$B$24:$F$28,6-N37,J37) | P37: =IF(AND(J37=5,OR(I37="Safety",I37="Environment")),"YES - life-safety override",IF(OR(O37="E",O37="H"),"YES",IF(O37="M","Justify & monitor","No"))) | S37: Because physical presence at the far end is assumed, the conduit must carry the security burden, not the endpoint. Command validation belongs at the receiving end. | U37: =J37*N37
A38: R-34 | B38: C-07 | C38: Market operator telemetry | D38: 3 | E38: Telemetry to the market operator is falsified, misrepresenting availability or capability. | F38: T0832 Manipulation of View; T1692 Unauthorized Message | G38: Protocol gateway trusts the internal source without integrity checking. | H38: S-06 | I38: Regulatory | J38: 4 | K38: 2 | L38: =INDEX(Scales!$B$24:$F$28,6-K38,J38) | M38: Dedicated market network. Gateway in the DMZ. | N38: 2 | O38: =INDEX(Scales!$B$24:$F$28,6-N38,J38) | P38: =IF(AND(J38=5,OR(I38="Safety",I38="Environment")),"YES - life-safety override",IF(OR(O38="E",O38="H"),"YES",IF(O38="M","Justify & monitor","No"))) | S38: Capped at Major because one 20 MW unit is not systemically significant alone. The same technique across a fleet is — and that is the honest framing. | U38: =J38*N38
A39: R-35 | B39: C-08 | C39: Control centre link | D39: 3 | E39: The portfolio control centre is compromised and its trusted supervisory link is used to dispatch the unit. | F39: T0886 Remote Services; T0831 Manipulation of Control | G39: The control centre is out of scope for this assessment and has no assessment of its own. | H39: S-05 | I39: Availability | J39: 4 | K39: 3 | L39: =INDEX(Scales!$B$24:$F$28,6-K39,J39) | M39: Operator-owned WAN. DMZ termination. | N39: 3 | O39: =INDEX(Scales!$B$24:$F$28,6-N39,J39) | P39: =IF(AND(J39=5,OR(I39="Safety",I39="Environment")),"YES - life-safety override",IF(OR(O39="E",O39="H"),"YES",IF(O39="M","Justify & monitor","No"))) | S39: ROUTE 2 — rated at direct consequence. A compromised control centre can dispatch the unit, which is a generation and market consequence. It does not by itself defeat protection. | T39: S-01 if combined with R-01 (protection defeat) — dispatch plus no protection | U39: =J39*N39
A40: R-36 | B40: C-11 | C40: Corporate IT boundary | D40: 2 | E40: The corporate network is compromised by commodity means and the DMZ is used as the route toward OT. | F40: T0865 Spearphishing Attachment; T0817 Drive-by Compromise; T0867 Lateral Tool Transfer | G40: Identity and patch distribution flow inbound from corporate, creating a trusted path. | H40: S-05 | I40: Availability | J40: 4 | K40: 4 | L40: =INDEX(Scales!$B$24:$F$28,6-K40,J40) | M40: DMZ firewall. Corporate EDR. | N40: 3 | O40: =INDEX(Scales!$B$24:$F$28,6-N40,J40) | P40: =IF(AND(J40=5,OR(I40="Safety",I40="Environment")),"YES - life-safety override",IF(OR(O40="E",O40="H"),"YES",IF(O40="M","Justify & monitor","No"))) | S40: The Colonial Pipeline pattern: IT compromise forcing an OT shutdown. The business-continuity argument for segregation, and the direct link to CIRMP s8C three-month independent operation. | U40: =J40*N40
A41: R-37 | B41: C-04 | C41: Historian collector | D41: 2 | E41: The historian collection path is used in reverse to reach the supervisory zone. | F41: T0867 Lateral Tool Transfer; T0869 Standard Application Layer Protocol | G41: Collector uses a bidirectional session where the data flow is logically one-way. | H41: S-07 | I41: Availability | J41: 4 | K41: 3 | L41: =INDEX(Scales!$B$24:$F$28,6-K41,J41) | M41: Firewall rules restrict to the collector port. | N41: 2 | O41: =INDEX(Scales!$B$24:$F$28,6-N41,J41) | P41: =IF(AND(J41=5,OR(I41="Safety",I41="Environment")),"YES - life-safety override",IF(OR(O41="E",O41="H"),"YES",IF(O41="M","Justify & monitor","No"))) | S41: Candidate for a unidirectional gateway. A data diode removes the inbound path rather than filtering it. | U41: =J41*N41
...

Sheet Scales
A1: Risk scales and matrix
A2: Carried from ZCR 4 (document 04). Do not edit without re-approving document 04.
A4: CONSEQUENCE
A5: Rating | B5: Descriptor | C5: Safety | D5: Environment | E5: Availability | F5: Financial | G5: Regulatory / reputation
A6: 5 | B6: Catastrophic | C6: Fatality, or multiple permanent disabilities | D6: Uncontained release with lasting harm; uncontrolled water release affecting third parties | E6: > 6 months outage | F6: > $10M | G6: Licence revocation; prosecution
A7: 4 | B7: Major | C7: Permanent disability; multiple lost-time injuries | D7: Reportable breach requiring remediation; environmental flow breach | E7: 1-6 months | F7: $1-10M | G7: Enforceable undertaking; mandatory report
A8: 3 | B8: Moderate | C8: Lost-time injury | D8: Reportable, remediable within licence | E8: 1-4 weeks | F8: $100k-1M | G8: Reportable incident; local coverage
A9: 2 | B9: Minor | C9: Medical treatment, no lost time | D9: Contained; internally reportable | E9: 1-7 days | F9: $10-100k | G9: Internal reporting only
A10: 1 | B10: Negligible | C10: First aid | D10: None | E10: < 1 day | F10: < $10k | G10: None
A13: LIKELIHOOD
A14: Rating | B14: Descriptor | C14: Guidance
A15: 5 | B15: Almost certain | C15: Expected within 12 months. Techniques are commodity; the path is exposed and requires no specialist knowledge.
A16: 4 | B16: Likely | C16: Expected within 1-3 years. Known techniques, moderate effort, path reachable from outside.
A17: 3 | B17: Possible | C17: Expected within 3-10 years. Requires IACS-specific knowledge or insider access; documented in the wild.
A18: 2 | B18: Unlikely | C18: Expected within 10-25 years. Requires sustained effort, specialist tooling and target-specific knowledge.
A19: 1 | B19: Rare | C19: Not expected. Requires extended resources directed at this specific asset.
A22: RISK MATRIX (lookup range B24:F28 — rows = likelihood 5..1, columns = consequence 1..5)
A23: L \ C | B23: 1 | C23: 2 | D23: 3 | E23: 4 | F23: 5
A24: 5 | B24: M | C24: H | D24: E | E24: E | F24: E
A25: 4 | B25: L | C25: M | D25: H | E25: E | F25: E
A26: 3 | B26: L | C26: M | D26: H | E26: H | F26: E
A27: 2 | B27: L | C27: L | D27: M | E27: H | F27: H
A28: 1 | B28: L | C28: L | D28: L | E28: M | F28: H
A30: ACCEPTANCE CRITERIA
A31: Band | B31: Treatment | C31: Authority to accept | D31: Timeframe
A32: E | B32: Not tolerable under any circumstances. Treat to High or below. Interim control plus time-bound derogation if treatment is not immediately achievable. | E32: Board or equivalent governing body — cannot be accepted at site or asset-manager level | G32: Interim 30 days; plan 90 days
A33: H | B33: Not tolerable without treatment. Treatment plan required with named owner and date. | E33: Asset owner executive | G33: Treat within 12 months
A34: M | B34: Tolerable with documented justification and monitoring. Treat where reasonably practicable. | E34: Asset manager | G34: Review annually
A35: L | B35: Tolerable. Monitor through routine review. | E35: Site | G35: Review each cycle
A38: OVERRIDES — these beat the matrix
A39: 1. Safety consequence 5 is never accepted on likelihood grounds alone. Any credible path to fatality requires treatment regardless of band.
A40: 2. No treatment may be applied inside a protective function. Treatment must act on management interfaces, access or detection — never on the protective action itself.

Sheet ATT&CK mapping
A1: MITRE ATT&CK for ICS — technique mapping
A2: Content version v19.2, verified 14 Sept 2026 against attack.mitre.org/techniques/ics/. IDs are version-sensitive — see the note below the table.
A4: Technique ID | B4: Technique name | C4: ATT&CK tactic (primary) | D4: Used in risk IDs | E4: Why it matters here | F4: ID verified v19.2
A5: T0809 | B5: Data Destruction | C5: Impact | D5: R-18 | E5: Encrypting or wiping controller logic, relay settings and backups together is what converts a recoverable incident into an unrecoverable one. | F5: Yes
A6: T0811 | B6: Data from Information Repositories | C6: Collection | D6: R-20 | E6: Engineering documentation is the reconnaissance that makes a targeted logic change feasible. | F6: Yes
A7: T0813 | B7: Denial of Control | C7: Impact | D7: R-08, R-11 | E7: Operators lose the ability to act while the process continues. | F7: Yes
A8: T0814 | B8: Denial of Service | C8: Impact | D8: R-15 | E8: An unattended station with no supervisory path is running blind. | F8: Yes
A9: T0815 | B9: Denial of View | C9: Impact | D9: R-15 | E9: Paired with T0814; the control centre sees nothing. | F9: Yes
A10: T0816 | B10: Device Restart/Shutdown | C10: Inhibit Response Function | D10: R-07 | E10: A PLC restart at the wrong moment suspends interlock execution. | F10: Yes
A11: T0817 | B11: Drive-by Compromise | C11: Initial Access | D11: R-36 | E11: The commodity entry point into corporate IT that precedes the OT-facing move. | F11: Yes
A12: T0819 | B12: Exploit Public-Facing Application | C12: Initial Access | D12: R-29 | E12: The DMZ is internet-reachable by design; patch cadence is tied to outage windows. | F12: Yes
A13: T0821 | B13: Modify Controller Tasking | C13: Impair Process Control | D13: R-21 | E13: Changing what the controller executes, not merely its parameters. | F13: Yes
A14: T0822 | B14: External Remote Services | C14: Initial Access | D14: R-25, R-28, R-31 | E14: The vendor path and the cellular backup path are both external remote services. | F14: Yes
A15: T0826 | B15: Loss of Availability | C15: Impact | D15: R-18 | E15: The SOCI 12-hour reporting trigger when OT is offline. | F15: Yes
... A47: T1694 | B47: Insecure Credentials | C47: Credential Access | D47: R-17, R-32 | E47: Supersedes T0891 Hardcoded Credentials. The Oldsmar technique. | F47: Yes
A49: VERSION NOTE
A50: ATT&CK for ICS technique IDs are version-sensitive and several were restructured before v19.2. Material written against earlier releases cites T0855 (Unauthorized Command Message), T0856 (Spoof Reporting Message), T0803/T0804 (Block Command/Reporting Message), T0857/T0839 (System/Module Firmware) and T0891 (Hardcoded Credentials). All are superseded by T1691-T1695 in the current release. Re-verify this sheet against the live matrix whenever the assessment is refreshed, and record the version you verified against.

Sheet SL gap
A1: Security level gap — SL-T against SL-A
A2: The operating loop: assess SL-A against SL-T; the delta is the remediation backlog. SL-C is what the components are capable of, as declared by the vendor.
A4: Zone / Conduit | B4: Name | C4: SL-T (target) | D4: SL-C (capable) | E4: SL-A (achieved) | F4: Gap (T-A) | G4: Principal shortfall driving the gap | H4: Governing risk IDs
A5: Z-01 | B5: Protection and trip | C5: 3 | D5: 2 | E5: 1 | F5: =C5-E5 | G5: No per-user authentication on relay management; no integrity verification of settings or firmware; setting changes detected only by annual test. | H5: R-01, R-02, R-04
A6: Z-02 | B6: Unit control | C6: 3 | D6: 2 | E6: 1 | F6: =C6-E6 | G6: Governor programming interface has no user authentication; logic not integrity-checked after download; PLC mode change unalarmed. | H6: R-05, R-06, R-07
A7: Z-03 | B7: Station auxiliaries | C7: 2 | D7: 2 | E7: 1 | F7: =C7-E7 | G7: No setpoint baselining or change alerting; inhibit states unmonitored. | H7: R-10, R-11
A8: Z-04 | B8: Supervisory control | C8: 2 | D8: 2 | E8: 1 | F8: =C8-E8 | G8: Shared operator account; no MFA; alarm configuration changes not independently logged. | H8: R-14, R-17
A9: Z-05a | B9: Engineering | C9: 3 | D9: 3 | E9: 1 | F9: =C9-E9 | G9: Backups on-site, same domain, reachable from the host that would be encrypted, and never restore-tested. Project files and toolchain unsigned. | H9: R-18, R-19, R-21
A10: Z-05b | B10: Plant information | C10: 2 | D10: 3 | E10: 2 | F10: =C10-E10 | G10: Read-mostly historian and documentation store. Achieves its lower target already — the gap closes by SEPARATION, not by spend. This row is the argument for the split. | H10: R-20
A11: Z-06 | B11: Intake and weir | C11: 3 | D11: 1 | E11: 1 | F11: =C11-E11 | G11: DNP3 without Secure Authentication (RTU capability unconfirmed); physical access uncontrolled; single level source with no independent cross-check. | H11: R-22, R-23, R-24
A12: Z-07 | B12: Transient and externally connected | C12: 3 | D12: 1 | E12: 1 | F12: =C12-E12 | G12: No pre-connection scanning, no dedicated site laptops, no port security on control-zone switches, no media sanitisation. | H12: R-26, R-27
A13: Z-08 | B13: Site DMZ | C13: 3 | D13: 3 | E13: 2 | F13: =C13-E13 | G13: Session recording not enabled on the jump host; firewall rule set not automatically compared against the conduit register. | H13: R-28, R-30
A14: C-06 | B14: Intake conduit | C14: 3 | D14: 1 | E14: 1 | F14: =C14-E14 | G14: Unauthenticated protocol over a radio link whose far end is physically accessible. Commands trusted on receipt rather than validated at the receiving end. | H14: R-33
A15: C-09 | B15: Vendor remote access | C15: 3 | D15: 2 | E15: 1 | F15: =C15-E15 | G15: Shared per-vendor accounts; no just-in-time approval; no session recording; no 62443-2-4 obligations in the service contract. | H15: R-31, R-32
A17: READ THIS BEFORE QUOTING THE NUMBERS
A18: SL-A values are the assessor's estimate from documented configuration, not from testing. They are the most uncertain figures in the workbook and should be replaced by measured values after a configuration review. An SL-A stated without evidence is an opinion wearing a number.
A19: SL-C for Z-06 and C-06 is 1 pending confirmation that the intake RTU supports DNP3 Secure Authentication. If it does not, SL-T 3 on that conduit is not achievable by configuration and becomes a procurement item — which is exactly the kind of finding the CRS exists to force a supplier to answer.
A20: SL-C is a vendor claim. A component with SL-C 3 badly configured achieves less; a component with SL-C 1 cannot reach SL-T 3 however well configured. Where SL-C is below SL-T, the remediation belongs in procurement, not in engineering.
A21: Maturity level and security level have no relationship to each other. ML (62443-2-1 and -2-4) describes how institutionalised a process is; SL describes what attacker capability a system withstands. An organisation at ML 3 can operate a zone at SL 1.

Sheet Attack path
A1: Attack path — where the enabler risks lead
A2: Route 2 rates each risk at the consequence it DIRECTLY achieves. The escalation chains that rating removes from the consequence column are carried here instead, so the link to the fatality scenarios stays visible and auditable. Nothing has been dropped; it has been moved to where it can be reasoned about as a path.
A4: Enabler | B4: Directly achieves | C4: Next step required | D4: Control standing in the way | E4: Ends at | F4: Breaks if
A5: R-12 Auxiliaries PLC as pivot | B5: S-08 loss of auxiliaries (4) | C5: Cross C-03 into Z-02 | D5: C-03 boundary; CRS-011 write allow-list | E5: S-01 machine loss (5) | F5: CRS-011 is delivered as an unrestricted permit rule
A6: R-17 Operator credentials | B6: S-05 loss of generation (4) | C6: Reuse credential against the governor programming interface | D6: CRS-008 per-user authentication on the programming interface | E6: S-01 machine loss (5) | F6: The governor keeps a shared engineering account
A7: R-20 Historian exfiltration | B7: S-09 regulatory / disclosure (3) | C7: Use settings and diagrams to target R-05 and R-19 | D7: None — this is reconnaissance, not access | E7: Shortens the path to S-01, S-04 | F7: Never; this risk has no failure mode of its own, only a contribution
A8: R-26 Contaminated maintenance laptop | B8: S-05 loss of generation (4) | C8: Deliberate process manipulation from inside the zone | D8: CRS-009 hydraulic closure-rate limit; GC-2 independent trip | E8: S-01 / S-02 (5) | F8: A-01 is false, or CRS-009 is enforced in governor logic
A9: R-35 Control centre link abuse | B9: S-05 loss of generation (4) | C9: Combine with protection defeat (R-01) | D9: CRS-007 no remote path to Z-01 management | E9: S-01 machine loss (5) | F9: CRS-007 is traded away for vendor remote setting change
A10: R-38 Supervisory-to-unit-control writes | B10: S-05 loss of generation (4) | C10: Drive the machine past a mechanical limit | D10: GC-2 hardwired overspeed trip; CRS-009 orifice | E10: S-01 machine loss (5) | F10: A-01 is false
A11: R-39 Transient physical connection | B11: S-05 loss of generation (4) | C11: Drive the machine past a mechanical limit | D11: GC-2 hardwired overspeed trip; CRS-009 orifice | E11: S-01 / S-02 (5) | F11: A-01 is false, or CRS-009 is enforced in governor logic
A13: THE SINGLE POINT THIS SHEET DEPENDS ON
A14: Five of the seven chains above are stopped by the same two things: the hardwired overspeed trip (assumption A-01, contracted as GC-2) and the hydraulic closure-rate limit (CRS-009, required to sit outside programmable logic).
A15: That makes A-01 the most load-bearing assumption in the whole assessment. If it is false, six risks return to consequence 5, the Extreme band goes back to 17, and Z-02's target security level rises to SL 4.
A16: A-01 is therefore not a footnote. It is the first thing to verify on site, by witnessing an overspeed test with the governor de-energised — and until it is verified, this register is conditional.

Sheet Treatment plan
A1: Treatment plan
A2: Every risk whose residual band is Extreme or High, or which trips the ZCR 4 life-safety override. ORDER THIS SHEET ON COLUMN I, PRIORITY SCORE (consequence x residual likelihood) — that is the answer to 'what do I fund first'. The life-safety override in column C is a separate constraint: those rows may not be deferred on likelihood grounds no matter where they rank.
A4: Risk ID | B4: Residual band | C4: Treatment required? | D4: Proposed treatment | E4: Acts on | F4: Authority to accept if untreated | G4: Owner | H4: Target | I4: Priority score
A5: R-22 | B5: ='Risk register'!O26 | C5: ='Risk register'!P26 | D5: Intrusion detection and camera at the intake; tamper alarm on the RTU enclosure reported to the control centre; command validation at the RTU against independently sensed level so a single falsified input cannot move a gate. | E5: Detection + design | F5: Board | I5: ='Risk register'!U26
A6: R-32 | B6: ='Risk register'!O36 | C6: ='Risk register'!P36 | D6: Per-individual named vendor accounts; phishing-resistant MFA (CIRMP s8B); just-in-time time-boxed approval tied to a work order with an operator enabling the session; full session recording with mid-session termination. | E6: Access | F6: Board | I6: ='Risk register'!U36
A7: R-18 | B7: ='Risk register'!O22 | C7: ='Risk register'!P22 | D7: Off-site immutable backup outside the plant domain and unreachable from the engineering workstation; quarterly restore test to a known-good state; recovery time measured, not assumed. | E7: Recovery | F7: Board | I7: ='Risk register'!U22
A8: R-26 | B8: ='Risk register'!O30 | C8: ='Risk register'!P30 | D8: Dedicated site-controlled laptops; pre-connection scanning; 802.1X or port security on control-zone switches; spare ports administratively disabled. | E8: Access | F8: Board | I8: ='Risk register'!U30
A9: R-30 | B9: ='Risk register'!O34 | C9: ='Risk register'!P34 | D9: Automated comparison of implemented firewall flows against the conduit register, run weekly; any drift raised as a finding. | E9: Detection | F9: Board | I9: ='Risk register'!U34
A10: R-39 | B10: ='Risk register'!O43 | C10: ='Risk register'!P43 | D10: 802.1X or port security on control-zone switches; physical port locks in cabinets; connection log. | E10: Access | F10: Board | I10: ='Risk register'!U43
A11: R-36 | B11: ='Risk register'!O40 | C11: ='Risk register'!P40 | D11: Segregation supporting independent operation (CIRMP s8C); remove the inbound trust from corporate for identity and patching, or broker it; test the islanded mode. | E11: Design | F11: Board | I11: ='Risk register'!U40
A12: R-01 | B12: ='Risk register'!O5 | C12: ='Risk register'!P5 | D12: Independent verification of relay settings against an approved schedule after every change; setting-change alerting to the control centre; per-user authentication on relay management. | E12: Management interface | F12: Executive | I12: ='Risk register'!U5
A13: R-02 | B13: ='Risk register'!O6 | C13: ='Risk register'!P6 | D13: Alarm out-of-service state to the control centre; periodic automated confirmation that trip outputs are enabled. NOTE: no control may be placed in the trip path itself. | E13: Detection | F13: Executive | I13: ='Risk register'!U6
A14: R-05 | B14: ='Risk register'!O9 | C14: ='Risk register'!P9 | D14: Confirm assumption A-01 by inspection. Per-user authentication on the governor programming interface; integrity check of logic after download against a golden copy. | E14: Management interface | F14: Executive | I14: ='Risk register'!U9
A15: R-06 | B15: ='Risk register'!O10 | C15: ='Risk register'!P10 | D15: Establish where the closure-rate limit is enforced. If software-only, add an independent mechanical or hardwired limit. | E15: Design | F15: Executive | I15: ='Risk register'!U10
A16: R-12 | B16: ='Risk register'!O16 | C16: ='Risk register'!P16 | D16: Restrict conduit C-03 to the permissive exchange only; deny general traffic between Z-03 and Z-02. | E16: Design | F16: Executive | I16: ='Risk register'!U16
A17: R-17 | B17: ='Risk register'!O21 | C17: ='Risk register'!P21 | D17: Per-individual operator accounts; MFA on the supervisory zone; remove shared credentials. | E17: Access | F17: Executive | I17: ='Risk register'!U21
A18: R-19 | B18: ='Risk register'!O23 | C18: ='Risk register'!P23 | D18: Sign or hash project files; golden-copy comparison before every download. | E18: Design | F18: Executive | I18: ='Risk register'!U23
A19: R-21 | B19: ='Risk register'!O25 | C19: ='Risk register'!P25 | D19: Separate the engineering toolchain from the historian host; separation of duty between relay, governor and PLC programming. | E19: Design | F19: Executive | I19: ='Risk register'!U25
A20: R-23 | B20: ='Risk register'!O27 | C20: ='Risk register'!P27 | D20: Confirm RTU support for DNP3 Secure Authentication. If unsupported, treat as a procurement item — SL-T 3 is not achievable by configuration. | E20: Design | F20: Executive | I20: ='Risk register'!U27
A21: R-24 | B21: ='Risk register'!O28 | C21: ='Risk register'!P28 | D21: Second independent level source with a divergence alarm. | E21: Design | F21: Executive | I21: ='Risk register'!U28
A22: R-25 | B22: ='Risk register'!O29 | C22: ='Risk register'!P29 | D22: Per-device certificate on the cellular path; bring the standby path up only on demand. | E22: Access | F22: Executive | I22: ='Risk register'!U29
A23: R-27 | B23: ='Risk register'!O31 | C23: ='Risk register'!P31 | D23: Media sanitisation station; USB port control on the engineering workstation. | E23: Access | F23: Executive | I23: ='Risk register'!U31
A24: R-28 | B24: ='Risk register'!O32 | C24: ='Risk register'!P32 | D24: Enable session recording on the jump host; reduce its reachable set to one asset and one protocol per session. | E24: Access | F24: Executive | I24: ='Risk register'!U32
